Workbook

Sheet Сверка
A1: Ежедневная сверка учёта с отчётами PSP
A2: Сентябрь 2026 · 3 PSP · собственный проект на синтетических данных, суммы в рублях
A4: Фильтр PSP: | B4: Все | C4: Порог match rate: | D4: 0.99
A6: Транзакций | B6: Расхождений | C6: Match rate | D6: Открыто / в работе | E6: Сумма открытых
A7: =SUMIFS(data_сверка!$C$2:$C$91,data_сверка!$B$2:$B$91,IF($B$4="Все","*",$B$4)) -> 11738 | B7: =SUMIFS(data_сверка!$D$2:$D$91,data_сверка!$B$2:$B$91,IF($B$4="Все","*",$B$4)) -> 53 | C7: =IFERROR(1-B7/A7,0) -> 0.99548475 | D7: =COUNTIFS(data_журнал!$C$2:$C$54,IF($B$4="Все","*",$B$4),data_журнал!$H$2:$H$54,"<>Закрыто") -> 7 | E7: =SUMIFS(data_журнал!$F$2:$F$54,data_журнал!$C$2:$C$54,IF($B$4="Все","*",$B$4),data_журнал!$H$2:$H$54,"<>Закрыто") -> 56112.32
A10: Итоги по PSP
A11: PSP | B11: Транзакций | C11: Расхождений | D11: Match rate | E11: Ниже порога, дней
A12: PSP Alfa | B12: =SUMIFS(data_сверка!$C$2:$C$91,data_сверка!$B$2:$B$91,$A12) -> 5699 | C12: =SUMIFS(data_сверка!$D$2:$D$91,data_сверка!$B$2:$B$91,$A12) -> 8 | D12: =IFERROR(1-C12/B12,0) -> 0.99859624 | E12: =COUNTIF($H$19:$H$48,"<"&$D$4) -> 1
A13: PSP Beta | B13: =SUMIFS(data_сверка!$C$2:$C$91,data_сверка!$B$2:$B$91,$A13) -> 3866 | C13: =SUMIFS(data_сверка!$D$2:$D$91,data_сверка!$B$2:$B$91,$A13) -> 7 | D13: =IFERROR(1-C13/B13,0) -> 0.99818934 | E13: =COUNTIF($I$19:$I$48,"<"&$D$4) -> 2
A14: PSP Gamma | B14: =SUMIFS(data_сверка!$C$2:$C$91,data_сверка!$B$2:$B$91,$A14) -> 2173 | C14: =SUMIFS(data_сверка!$D$2:$D$91,data_сверка!$B$2:$B$91,$A14) -> 38 | D14: =IFERROR(1-C14/B14,0) -> 0.98251266 | E14: =COUNTIF($J$19:$J$48,"<"&$D$4) -> 22
A16: Расхождения по типам | G16: Match rate по дням
A17: Тип | B17: PSP Alfa | C17: PSP Beta | D17: PSP Gamma
A18: Статус | B18: =COUNTIFS(data_журнал!$E$2:$E$54,$A18,data_журнал!$C$2:$C$54,"PSP Alfa") -> 2 | C18: =COUNTIFS(data_журнал!$E$2:$E$54,$A18,data_журнал!$C$2:$C$54,"PSP Beta") -> 3 | D18: =COUNTIFS(data_журнал!$E$2:$E$54,$A18,data_журнал!$C$2:$C$54,"PSP Gamma") -> 3 | G18: Дата | H18: PSP Alfa | I18: PSP Beta | J18: PSP Gamma
A19: Сумма | B19: =COUNTIFS(data_журнал!$E$2:$E$54,$A19,data_журнал!$C$2:$C$54,"PSP Alfa") -> 1 | C19: =COUNTIFS(data_журнал!$E$2:$E$54,$A19,data_журнал!$C$2:$C$54,"PSP Beta") -> 2 | D19: =COUNTIFS(data_журнал!$E$2:$E$54,$A19,data_журнал!$C$2:$C$54,"PSP Gamma") -> 9 | G19: 46266 | H19: =IFERROR(1-SUMIFS(data_сверка!$D$2:$D$91,data_сверка!$A$2:$A$91,$G19,data_сверка!$B$2:$B$91,"PSP Alfa")/SUMIFS(data_сверка!$C$2:$C$91,data_сверка!$A$2:$A$91,$G19,data_сверка!$B$2:$B$91,"PSP Alfa"),"") -> 1 | I19: =IFERROR(1-SUMIFS(data_сверка!$D$2:$D$91,data_сверка!$A$2:$A$91,$G19,data_сверка!$B$2:$B$91,"PSP Beta")/SUMIFS(data_сверка!$C$2:$C$91,data_сверка!$A$2:$A$91,$G19,data_сверка!$B$2:$B$91,"PSP Beta"),"") -> 1 | J19: =IFERROR(1-SUMIFS(data_сверка!$D$2:$D$91,data_сверка!$A$2:$A$91,$G19,data_сверка!$B$2:$B$91,"PSP Gamma")/SUMIFS(data_сверка!$C$2:$C$91,data_сверка!$A$2:$A$91,$G19,data_сверка!$B$2:$B$91,"PSP Gamma"),"") -> 0.98701299
A20: Комиссия | B20: =COUNTIFS(data_журнал!$E$2:$E$54,$A20,data_журнал!$C$2:$C$54,"PSP Alfa") -> 2 | C20: =COUNTIFS(data_журнал!$E$2:$E$54,$A20,data_журнал!$C$2:$C$54,"PSP Beta") -> 0 | D20: =COUNTIFS(data_журнал!$E$2:$E$54,$A20,data_журнал!$C$2:$C$54,"PSP Gamma") -> 10 | G20: 46267 | H20: =IFERROR(1-SUMIFS(data_сверка!$D$2:$D$91,data_сверка!$A$2:$A$91,$G20,data_сверка!$B$2:$B$91,"PSP Alfa")/SUMIFS(data_сверка!$C$2:$C$91,data_сверка!$A$2:$A$91,$G20,data_сверка!$B$2:$B$91,"PSP Alfa"),"") -> 1 | I20: =IFERROR(1-SUMIFS(data_сверка!$D$2:$D$91,data_сверка!$A$2:$A$91,$G20,data_сверка!$B$2:$B$91,"PSP Beta")/SUMIFS(data_сверка!$C$2:$C$91,data_сверка!$A$2:$A$91,$G20,data_сверка!$B$2:$B$91,"PSP Beta"),"") -> 1 | J20: =IFERROR(1-SUMIFS(data_сверка!$D$2:$D$91,data_сверка!$A$2:$A$91,$G20,data_сверка!$B$2:$B$91,"PSP Gamma")/SUMIFS(data_сверка!$C$2:$C$91,data_сверка!$A$2:$A$91,$G20,data_сверка!$B$2:$B$91,"PSP Gamma"),"") -> 0.984375
A21: Нет у PSP | B21: =COUNTIFS(data_журнал!$E$2:$E$54,$A21,data_журнал!$C$2:$C$54,"PSP Alfa") -> 2 | C21: =COUNTIFS(data_журнал!$E$2:$E$54,$A21,data_журнал!$C$2:$C$54,"PSP Beta") -> 1 | D21: =COUNTIFS(data_журнал!$E$2:$E$54,$A21,data_журнал!$C$2:$C$54,"PSP Gamma") -> 7 | G21: 46268 | H21: =IFERROR(1-SUMIFS(data_сверка!$D$2:$D$91,data_сверка!$A$2:$A$91,$G21,data_сверка!$B$2:$B$91,"PSP Alfa")/SUMIFS(data_сверка!$C$2:$C$91,data_сверка!$A$2:$A$91,$G21,data_сверка!$B$2:$B$91,"PSP Alfa"),"") -> 1 | I21: =IFERROR(1-SUMIFS(data_сверка!$D$2:$D$91,data_сверка!$A$2:$A$91,$G21,data_сверка!$B$2:$B$91,"PSP Beta")/SUMIFS(data_сверка!$C$2:$C$91,data_сверка!$A$2:$A$91,$G21,data_сверка!$B$2:$B$91,"PSP Beta"),"") -> 1 | J21: =IFERROR(1-SUMIFS(data_сверка!$D$2:$D$91,data_сверка!$A$2:$A$91,$G21,data_сверка!$B$2:$B$91,"PSP Gamma")/SUMIFS(data_сверка!$C$2:$C$91,data_сверка!$A$2:$A$91,$G21,data_сверка!$B$2:$B$91,"PSP Gamma"),"") -> 0.9875
A22: Нет в учёте | B22: =COUNTIFS(data_журнал!$E$2:$E$54,$A22,data_журнал!$C$2:$C$54,"PSP Alfa") -> 1 | C22: =COUNTIFS(data_журнал!$E$2:$E$54,$A22,data_журнал!$C$2:$C$54,"PSP Beta") -> 1 | D22: =COUNTIFS(data_журнал!$E$2:$E$54,$A22,data_журнал!$C$2:$C$54,"PSP Gamma") -> 9 | G22: 46269 | H22: =IFERROR(1-SUMIFS(data_сверка!$D$2:$D$91,data_сверка!$A$2:$A$91,$G22,data_сверка!$B$2:$B$91,"PSP Alfa")/SUMIFS(data_сверка!$C$2:$C$91,data_сверка!$A$2:$A$91,$G22,data_сверка!$B$2:$B$91,"PSP Alfa"),"") -> 1 | I22: =IFERROR(1-SUMIFS(data_сверка!$D$2:$D$91,data_сверка!$A$2:$A$91,$G22,data_сверка!$B$2:$B$91,"PSP Beta")/SUMIFS(data_сверка!$C$2:$C$91,data_сверка!$A$2:$A$91,$G22,data_сверка!$B$2:$B$91,"PSP Beta"),"") -> 1 | J22: =IFERROR(1-SUMIFS(data_сверка!$D$2:$D$91,data_сверка!$A$2:$A$91,$G22,data_сверка!$B$2:$B$91,"PSP Gamma")/SUMIFS(data_сверка!$C$2:$C$91,data_сверка!$A$2:$A$91,$G22,data_сверка!$B$2:$B$91,"PSP Gamma"),"") -> 1
G23: 46270 | H23: =IFERROR(1-SUMIFS(data_сверка!$D$2:$D$91,data_сверка!$A$2:$A$91,$G23,data_сверка!$B$2:$B$91,"PSP Alfa")/SUMIFS(data_сверка!$C$2:$C$91,data_сверка!$A$2:$A$91,$G23,data_сверка!$B$2:$B$91,"PSP Alfa"),"") -> 1 | I23: =IFERROR(1-SUMIFS(data_сверка!$D$2:$D$91,data_сверка!$A$2:$A$91,$G23,data_сверка!$B$2:$B$91,"PSP Beta")/SUMIFS(data_сверка!$C$2:$C$91,data_сверка!$A$2:$A$91,$G23,data_сверка!$B$2:$B$91,"PSP Beta"),"") -> 1 | J23: =IFERROR(1-SUMIFS(data_сверка!$D$2:$D$91,data_сверка!$A$2:$A$91,$G23,data_сверка!$B$2:$B$91,"PSP Gamma")/SUMIFS(data_сверка!$C$2:$C$91,data_сверка!$A$2:$A$91,$G23,data_сверка!$B$2:$B$91,"PSP Gamma"),"") -> 1
G24: 46271 | H24: =IFERROR(1-SUMIFS(data_сверка!$D$2:$D$91,data_сверка!$A$2:$A$91,$G24,data_сверка!$B$2:$B$91,"PSP Alfa")/SUMIFS(data_сверка!$C$2:$C$91,data_сверка!$A$2:$A$91,$G24,data_сверка!$B$2:$B$91,"PSP Alfa"),"") -> 1 | I24: =IFERROR(1-SUMIFS(data_сверка!$D$2:$D$91,data_сверка!$A$2:$A$91,$G24,data_сверка!$B$2:$B$91,"PSP Beta")/SUMIFS(data_сверка!$C$2:$C$91,data_сверка!$A$2:$A$91,$G24,data_сверка!$B$2:$B$91,"PSP Beta"),"") -> 1 | J24: =IFERROR(1-SUMIFS(data_сверка!$D$2:$D$91,data_сверка!$A$2:$A$91,$G24,data_сверка!$B$2:$B$91,"PSP Gamma")/SUMIFS(data_сверка!$C$2:$C$91,data_сверка!$A$2:$A$91,$G24,data_сверка!$B$2:$B$91,"PSP Gamma"),"") -> 0.97333333
A25: Как читать: желтые ячейки — фильтр и порог, их можно менять. Красным подсвечены дни и PSP ниже порога. | G25: 46272 | H25: =IFERROR(1-SUMIFS(data_сверка!$D$2:$D$91,data_сверка!$A$2:$A$91,$G25,data_сверка!$B$2:$B$91,"PSP Alfa")/SUMIFS(data_сверка!$C$2:$C$91,data_сверка!$A$2:$A$91,$G25,data_сверка!$B$2:$B$91,"PSP Alfa"),"") -> 1 | I25: =IFERROR(1-SUMIFS(data_сверка!$D$2:$D$91,data_сверка!$A$2:$A$91,$G25,data_сверка!$B$2:$B$91,"PSP Beta")/SUMIFS(data_сверка!$C$2:$C$91,data_сверка!$A$2:$A$91,$G25,data_сверка!$B$2:$B$91,"PSP Beta"),"") -> 1 | J25: =IFERROR(1-SUMIFS(data_сверка!$D$2:$D$91,data_сверка!$A$2:$A$91,$G25,data_сверка!$B$2:$B$91,"PSP Gamma")/SUMIFS(data_сверка!$C$2:$C$91,data_сверка!$A$2:$A$91,$G25,data_сверка!$B$2:$B$91,"PSP Gamma"),"") -> 0.953125
G26: 46273 | H26: =IFERROR(1-SUMIFS(data_сверка!$D$2:$D$91,data_сверка!$A$2:$A$91,$G26,data_сверка!$B$2:$B$91,"PSP Alfa")/SUMIFS(data_сверка!$C$2:$C$91,data_сверка!$A$2:$A$91,$G26,data_сверка!$B$2:$B$91,"PSP Alfa"),"") -> 1 | I26: =IFERROR(1-SUMIFS(data_сверка!$D$2:$D$91,data_сверка!$A$2:$A$91,$G26,data_сверка!$B$2:$B$91,"PSP Beta")/SUMIFS(data_сверка!$C$2:$C$91,data_сверка!$A$2:$A$91,$G26,data_сверка!$B$2:$B$91,"PSP Beta"),"") -> 1 | J26: =IFERROR(1-SUMIFS(data_сверка!$D$2:$D$91,data_сверка!$A$2:$A$91,$G26,data_сверка!$B$2:$B$91,"PSP Gamma")/SUMIFS(data_сверка!$C$2:$C$91,data_сверка!$A$2:$A$91,$G26,data_сверка!$B$2:$B$91,"PSP Gamma"),"") -> 0.98360656
G27: 46274 | H27: =IFERROR(1-SUMIFS(data_сверка!$D$2:$D$91,data_сверка!$A$2:$A$91,$G27,data_сверка!$B$2:$B$91,"PSP Alfa")/SUMIFS(data_сверка!$C$2:$C$91,data_сверка!$A$2:$A$91,$G27,data_сверка!$B$2:$B$91,"PSP Alfa"),"") -> 1 | I27: =IFERROR(1-SUMIFS(data_сверка!$D$2:$D$91,data_сверка!$A$2:$A$91,$G27,data_сверка!$B$2:$B$91,"PSP Beta")/SUMIFS(data_сверка!$C$2:$C$91,data_сверка!$A$2:$A$91,$G27,data_сверка!$B$2:$B$91,"PSP Beta"),"") -> 1 | J27: =IFERROR(1-SUMIFS(data_сверка!$D$2:$D$91,data_сверка!$A$2:$A$91,$G27,data_сверка!$B$2:$B$91,"PSP Gamma")/SUMIFS(data_сверка!$C$2:$C$91,data_сверка!$A$2:$A$91,$G27,data_сверка!$B$2:$B$91,"PSP Gamma"),"") -> 0.98387097
G28: 46275 | H28: =IFERROR(1-SUMIFS(data_сверка!$D$2:$D$91,data_сверка!$A$2:$A$91,$G28,data_сверка!$B$2:$B$91,"PSP Alfa")/SUMIFS(data_сверка!$C$2:$C$91,data_сверка!$A$2:$A$91,$G28,data_сверка!$B$2:$B$91,"PSP Alfa"),"") -> 0.9952381 | I28: =IFERROR(1-SUMIFS(data_сверка!$D$2:$D$91,data_сверка!$A$2:$A$91,$G28,data_сверка!$B$2:$B$91,"PSP Beta")/SUMIFS(data_сверка!$C$2:$C$91,data_сверка!$A$2:$A$91,$G28,data_сверка!$B$2:$B$91,"PSP Beta"),"") -> 1 | J28: =IFERROR(1-SUMIFS(data_сверка!$D$2:$D$91,data_сверка!$A$2:$A$91,$G28,data_сверка!$B$2:$B$91,"PSP Gamma")/SUMIFS(data_сверка!$C$2:$C$91,data_сверка!$A$2:$A$91,$G28,data_сверка!$B$2:$B$91,"PSP Gamma"),"") -> 1
G29: 46276 | H29: =IFERROR(1-SUMIFS(data_сверка!$D$2:$D$91,data_сверка!$A$2:$A$91,$G29,data_сверка!$B$2:$B$91,"PSP Alfa")/SUMIFS(data_сверка!$C$2:$C$91,data_сверка!$A$2:$A$91,$G29,data_сверка!$B$2:$B$91,"PSP Alfa"),"") -> 0.98701299 | I29: =IFERROR(1-SUMIFS(data_сверка!$D$2:$D$91,data_сверка!$A$2:$A$91,$G29,data_сверка!$B$2:$B$91,"PSP Beta")/SUMIFS(data_сверка!$C$2:$C$91,data_сверка!$A$2:$A$91,$G29,data_сверка!$B$2:$B$91,"PSP Beta"),"") -> 1 | J29: =IFERROR(1-SUMIFS(data_сверка!$D$2:$D$91,data_сверка!$A$2:$A$91,$G29,data_сверка!$B$2:$B$91,"PSP Gamma")/SUMIFS(data_сверка!$C$2:$C$91,data_сверка!$A$2:$A$91,$G29,data_сверка!$B$2:$B$91,"PSP Gamma"),"") -> 0.96923077
G30: 46277 | H30: =IFERROR(1-SUMIFS(data_сверка!$D$2:$D$91,data_сверка!$A$2:$A$91,$G30,data_сверка!$B$2:$B$91,"PSP Alfa")/SUMIFS(data_сверка!$C$2:$C$91,data_сверка!$A$2:$A$91,$G30,data_сверка!$B$2:$B$91,"PSP Alfa"),"") -> 1 | I30: =IFERROR(1-SUMIFS(data_сверка!$D$2:$D$91,data_сверка!$A$2:$A$91,$G30,data_сверка!$B$2:$B$91,"PSP Beta")/SUMIFS(data_сверка!$C$2:$C$91,data_сверка!$A$2:$A$91,$G30,data_сверка!$B$2:$B$91,"PSP Beta"),"") -> 1 | J30: =IFERROR(1-SUMIFS(data_сверка!$D$2:$D$91,data_сверка!$A$2:$A$91,$G30,data_сверка!$B$2:$B$91,"PSP Gamma")/SUMIFS(data_сверка!$C$2:$C$91,data_сверка!$A$2:$A$91,$G30,data_сверка!$B$2:$B$91,"PSP Gamma"),"") -> 0.98571429
G31: 46278 | H31: =IFERROR(1-SUMIFS(data_сверка!$D$2:$D$91,data_сверка!$A$2:$A$91,$G31,data_сверка!$B$2:$B$91,"PSP Alfa")/SUMIFS(data_сверка!$C$2:$C$91,data_сверка!$A$2:$A$91,$G31,data_сверка!$B$2:$B$91,"PSP Alfa"),"") -> 1 | I31: =IFERROR(1-SUMIFS(data_сверка!$D$2:$D$91,data_сверка!$A$2:$A$91,$G31,data_сверка!$B$2:$B$91,"PSP Beta")/SUMIFS(data_сверка!$C$2:$C$91,data_сверка!$A$2:$A$91,$G31,data_сверка!$B$2:$B$91,"PSP Beta"),"") -> 1 | J31: =IFERROR(1-SUMIFS(data_сверка!$D$2:$D$91,data_сверка!$A$2:$A$91,$G31,data_сверка!$B$2:$B$91,"PSP Gamma")/SUMIFS(data_сверка!$C$2:$C$91,data_сверка!$A$2:$A$91,$G31,data_сверка!$B$2:$B$91,"PSP Gamma"),"") -> 0.97530864
G32: 46279 | H32: =IFERROR(1-SUMIFS(data_сверка!$D$2:$D$91,data_сверка!$A$2:$A$91,$G32,data_сверка!$B$2:$B$91,"PSP Alfa")/SUMIFS(data_сверка!$C$2:$C$91,data_сверка!$A$2:$A$91,$G32,data_сверка!$B$2:$B$91,"PSP Alfa"),"") -> 1 | I32: =IFERROR(1-SUMIFS(data_сверка!$D$2:$D$91,data_сверка!$A$2:$A$91,$G32,data_сверка!$B$2:$B$91,"PSP Beta")/SUMIFS(data_сверка!$C$2:$C$91,data_сверка!$A$2:$A$91,$G32,data_сверка!$B$2:$B$91,"PSP Beta"),"") -> 1 | J32: =IFERROR(1-SUMIFS(data_сверка!$D$2:$D$91,data_сверка!$A$2:$A$91,$G32,data_сверка!$B$2:$B$91,"PSP Gamma")/SUMIFS(data_сверка!$C$2:$C$91,data_сверка!$A$2:$A$91,$G32,data_сверка!$B$2:$B$91,"PSP Gamma"),"") -> 0.97101449
G33: 46280 | H33: =IFERROR(1-SUMIFS(data_сверка!$D$2:$D$91,data_сверка!$A$2:$A$91,$G33,data_сверка!$B$2:$B$91,"PSP Alfa")/SUMIFS(data_сверка!$C$2:$C$91,data_сверка!$A$2:$A$91,$G33,data_сверка!$B$2:$B$91,"PSP Alfa"),"") -> 1 | I33: =IFERROR(1-SUMIFS(data_сверка!$D$2:$D$91,data_сверка!$A$2:$A$91,$G33,data_сверка!$B$2:$B$91,"PSP Beta")/SUMIFS(data_сверка!$C$2:$C$91,data_сверка!$A$2:$A$91,$G33,data_сверка!$B$2:$B$91,"PSP Beta"),"") -> 1 | J33: =IFERROR(1-SUMIFS(data_сверка!$D$2:$D$91,data_сверка!$A$2:$A$91,$G33,data_сверка!$B$2:$B$91,"PSP Gamma")/SUMIFS(data_сверка!$C$2:$C$91,data_сверка!$A$2:$A$91,$G33,data_сверка!$B$2:$B$91,"PSP Gamma"),"") -> 0.92647059
G34: 46281 | H34: =IFERROR(1-SUMIFS(data_сверка!$D$2:$D$91,data_сверка!$A$2:$A$91,$G34,data_сверка!$B$2:$B$91,"PSP Alfa")/SUMIFS(data_сверка!$C$2:$C$91,data_сверка!$A$2:$A$91,$G34,data_сверка!$B$2:$B$91,"PSP Alfa"),"") -> 1 | I34: =IFERROR(1-SUMIFS(data_сверка!$D$2:$D$91,data_сверка!$A$2:$A$91,$G34,data_сверка!$B$2:$B$91,"PSP Beta")/SUMIFS(data_сверка!$C$2:$C$91,data_сверка!$A$2:$A$91,$G34,data_сверка!$B$2:$B$91,"PSP Beta"),"") -> 0.98373984 | J34: =IFERROR(1-SUMIFS(data_сверка!$D$2:$D$91,data_сверка!$A$2:$A$91,$G34,data_сверка!$B$2:$B$91,"PSP Gamma")/SUMIFS(data_сверка!$C$2:$C$91,data_сверка!$A$2:$A$91,$G34,data_сверка!$B$2:$B$91,"PSP Gamma"),"") -> 0.96721311
G35: 46282 | H35: =IFERROR(1-SUMIFS(data_сверка!$D$2:$D$91,data_сверка!$A$2:$A$91,$G35,data_сверка!$B$2:$B$91,"PSP Alfa")/SUMIFS(data_сверка!$C$2:$C$91,data_сверка!$A$2:$A$91,$G35,data_сверка!$B$2:$B$91,"PSP Alfa"),"") -> 1 | I35: =IFERROR(1-SUMIFS(data_сверка!$D$2:$D$91,data_сверка!$A$2:$A$91,$G35,data_сверка!$B$2:$B$91,"PSP Beta")/SUMIFS(data_сверка!$C$2:$C$91,data_сверка!$A$2:$A$91,$G35,data_сверка!$B$2:$B$91,"PSP Beta"),"") -> 0.98449612 | J35: =IFERROR(1-SUMIFS(data_сверка!$D$2:$D$91,data_сверка!$A$2:$A$91,$G35,data_сверка!$B$2:$B$91,"PSP Gamma")/SUMIFS(data_сверка!$C$2:$C$91,data_сверка!$A$2:$A$91,$G35,data_сверка!$B$2:$B$91,"PSP Gamma"),"") -> 0.975
G36: 46283 | H36: =IFERROR(1-SUMIFS(data_сверка!$D$2:$D$91,data_сверка!$A$2:$A$91,$G36,data_сверка!$B$2:$B$91,"PSP Alfa")/SUMIFS(data_сверка!$C$2:$C$91,data_сверка!$A$2:$A$91,$G36,data_сверка!$B$2:$B$91,"PSP Alfa"),"") -> 1 | I36: =IFERROR(1-SUMIFS(data_сверка!$D$2:$D$91,data_сверка!$A$2:$A$91,$G36,data_сверка!$B$2:$B$91,"PSP Beta")/SUMIFS(data_сверка!$C$2:$C$91,data_сверка!$A$2:$A$91,$G36,data_сверка!$B$2:$B$91,"PSP Beta"),"") -> 1 | J36: =IFERROR(1-SUMIFS(data_сверка!$D$2:$D$91,data_сверка!$A$2:$A$91,$G36,data_сверка!$B$2:$B$91,"PSP Gamma")/SUMIFS(data_сверка!$C$2:$C$91,data_сверка!$A$2:$A$91,$G36,data_сверка!$B$2:$B$91,"PSP Gamma"),"") -> 1
G37: 46284 | H37: =IFERROR(1-SUMIFS(data_сверка!$D$2:$D$91,data_сверка!$A$2:$A$91,$G37,data_сверка!$B$2:$B$91,"PSP Alfa")/SUMIFS(data_сверка!$C$2:$C$91,data_сверка!$A$2:$A$91,$G37,data_сверка!$B$2:$B$91,"PSP Alfa"),"") -> 0.99494949 | I37: =IFERROR(1-SUMIFS(data_сверка!$D$2:$D$91,data_сверка!$A$2:$A$91,$G37,data_сверка!$B$2:$B$91,"PSP Beta")/SUMIFS(data_сверка!$C$2:$C$91,data_сверка!$A$2:$A$91,$G37,data_сверка!$B$2:$B$91,"PSP Beta"),"") -> 0.99350649 | J37: =IFERROR(1-SUMIFS(data_сверка!$D$2:$D$91,data_сверка!$A$2:$A$91,$G37,data_сверка!$B$2:$B$91,"PSP Gamma")/SUMIFS(data_сверка!$C$2:$C$91,data_сверка!$A$2:$A$91,$G37,data_сверка!$B$2:$B$91,"PSP Gamma"),"") -> 0.97802198
... G48: 46295 | H48: =IFERROR(1-SUMIFS(data_сверка!$D$2:$D$91,data_сверка!$A$2:$A$91,$G48,data_сверка!$B$2:$B$91,"PSP Alfa")/SUMIFS(data_сверка!$C$2:$C$91,data_сверка!$A$2:$A$91,$G48,data_сверка!$B$2:$B$91,"PSP Alfa"),"") -> 1 | I48: =IFERROR(1-SUMIFS(data_сверка!$D$2:$D$91,data_сверка!$A$2:$A$91,$G48,data_сверка!$B$2:$B$91,"PSP Beta")/SUMIFS(data_сверка!$C$2:$C$91,data_сверка!$A$2:$A$91,$G48,data_сверка!$B$2:$B$91,"PSP Beta"),"") -> 1 | J48: =IFERROR(1-SUMIFS(data_сверка!$D$2:$D$91,data_сверка!$A$2:$A$91,$G48,data_сверка!$B$2:$B$91,"PSP Gamma")/SUMIFS(data_сверка!$C$2:$C$91,data_сверка!$A$2:$A$91,$G48,data_сверка!$B$2:$B$91,"PSP Gamma"),"") -> 0.97333333

Sheet Журнал
A1: Журнал расхождений
A2: Каждое расхождение проходит путь «обнаружено → причина → закрыто». Статус и причину заполняет аналитик.
A4: Статус: | B4: Все
A6: Номер | B6: Дата | C6: PSP | D6: ID транзакции | E6: Тип | F6: Сумма, ₽ | G6: Причина | H6: Статус
A7: =IF(OR($B$4="Все",data_журнал!$H$2=$B$4),data_журнал!A2,"") -> BR-001 | B7: =IF(OR($B$4="Все",data_журнал!$H$2=$B$4),data_журнал!B2,"") -> 46266 | C7: =IF(OR($B$4="Все",data_журнал!$H$2=$B$4),data_журнал!C2,"") -> PSP Gamma | D7: =IF(OR($B$4="Все",data_журнал!$H$2=$B$4),data_журнал!D2,"") -> GAM-0901-0000 | E7: =IF(OR($B$4="Все",data_журнал!$H$2=$B$4),data_журнал!E2,"") -> Нет в учёте | F7: =IF(OR($B$4="Все",data_журнал!$H$2=$B$4),data_журнал!F2,"") -> 10601.75 | G7: =IF(OR($B$4="Все",data_журнал!$H$2=$B$4),data_журнал!G2,"") -> Возврат (refund) не загрузился во внутренний учёт | H7: =IF(OR($B$4="Все",data_журнал!$H$2=$B$4),data_журнал!H2,"") -> Закрыто
A8: =IF(OR($B$4="Все",data_журнал!$H$3=$B$4),data_журнал!A3,"") -> BR-002 | B8: =IF(OR($B$4="Все",data_журнал!$H$3=$B$4),data_журнал!B3,"") -> 46267 | C8: =IF(OR($B$4="Все",data_журнал!$H$3=$B$4),data_журнал!C3,"") -> PSP Gamma | D8: =IF(OR($B$4="Все",data_журнал!$H$3=$B$4),data_журнал!D3,"") -> GAM-0902-0000 | E8: =IF(OR($B$4="Все",data_журнал!$H$3=$B$4),data_журнал!E3,"") -> Нет у PSP | F8: =IF(OR($B$4="Все",data_журнал!$H$3=$B$4),data_журнал!F3,"") -> 11527.01 | G8: =IF(OR($B$4="Все",data_журнал!$H$3=$B$4),data_журнал!G3,"") -> Транзакция попала в выписку следующего дня (cut-off) | H8: =IF(OR($B$4="Все",data_журнал!$H$3=$B$4),data_журнал!H3,"") -> Закрыто
A9: =IF(OR($B$4="Все",data_журнал!$H$4=$B$4),data_журнал!A4,"") -> BR-003 | B9: =IF(OR($B$4="Все",data_журнал!$H$4=$B$4),data_журнал!B4,"") -> 46268 | C9: =IF(OR($B$4="Все",data_журнал!$H$4=$B$4),data_журнал!C4,"") -> PSP Gamma | D9: =IF(OR($B$4="Все",data_журнал!$H$4=$B$4),data_журнал!D4,"") -> GAM-0903-0000 | E9: =IF(OR($B$4="Все",data_журнал!$H$4=$B$4),data_журнал!E4,"") -> Нет у PSP | F9: =IF(OR($B$4="Все",data_журнал!$H$4=$B$4),data_журнал!F4,"") -> 12598.96 | G9: =IF(OR($B$4="Все",data_журнал!$H$4=$B$4),data_журнал!G4,"") -> Транзакция попала в выписку следующего дня (cut-off) | H9: =IF(OR($B$4="Все",data_журнал!$H$4=$B$4),data_журнал!H4,"") -> Закрыто
A10: =IF(OR($B$4="Все",data_журнал!$H$5=$B$4),data_журнал!A5,"") -> BR-004 | B10: =IF(OR($B$4="Все",data_журнал!$H$5=$B$4),data_журнал!B5,"") -> 46271 | C10: =IF(OR($B$4="Все",data_журнал!$H$5=$B$4),data_журнал!C5,"") -> PSP Gamma | D10: =IF(OR($B$4="Все",data_журнал!$H$5=$B$4),data_журнал!D5,"") -> GAM-0906-0000 | E10: =IF(OR($B$4="Все",data_журнал!$H$5=$B$4),data_журнал!E5,"") -> Комиссия | F10: =IF(OR($B$4="Все",data_журнал!$H$5=$B$4),data_журнал!F5,"") -> 888.5 | G10: =IF(OR($B$4="Все",data_журнал!$H$5=$B$4),data_журнал!G5,"") -> PSP применил старую тарифную сетку | H10: =IF(OR($B$4="Все",data_журнал!$H$5=$B$4),data_журнал!H5,"") -> Закрыто
A11: =IF(OR($B$4="Все",data_журнал!$H$6=$B$4),data_журнал!A6,"") -> BR-005 | B11: =IF(OR($B$4="Все",data_журнал!$H$6=$B$4),data_журнал!B6,"") -> 46271 | C11: =IF(OR($B$4="Все",data_журнал!$H$6=$B$4),data_журнал!C6,"") -> PSP Gamma | D11: =IF(OR($B$4="Все",data_журнал!$H$6=$B$4),data_журнал!D6,"") -> GAM-0906-0001 | E11: =IF(OR($B$4="Все",data_журнал!$H$6=$B$4),data_журнал!E6,"") -> Нет в учёте | F11: =IF(OR($B$4="Все",data_журнал!$H$6=$B$4),data_журнал!F6,"") -> 15744 | G11: =IF(OR($B$4="Все",data_журнал!$H$6=$B$4),data_журнал!G6,"") -> Возврат (refund) не загрузился во внутренний учёт | H11: =IF(OR($B$4="Все",data_журнал!$H$6=$B$4),data_журнал!H6,"") -> Закрыто
A12: =IF(OR($B$4="Все",data_журнал!$H$7=$B$4),data_журнал!A7,"") -> BR-006 | B12: =IF(OR($B$4="Все",data_журнал!$H$7=$B$4),data_журнал!B7,"") -> 46272 | C12: =IF(OR($B$4="Все",data_журнал!$H$7=$B$4),data_журнал!C7,"") -> PSP Gamma | D12: =IF(OR($B$4="Все",data_журнал!$H$7=$B$4),data_журнал!D7,"") -> GAM-0907-0000 | E12: =IF(OR($B$4="Все",data_журнал!$H$7=$B$4),data_журнал!E7,"") -> Нет в учёте | F12: =IF(OR($B$4="Все",data_журнал!$H$7=$B$4),data_журнал!F7,"") -> 9718.19 | G12: =IF(OR($B$4="Все",data_журнал!$H$7=$B$4),data_журнал!G7,"") -> Возврат (refund) не загрузился во внутренний учёт | H12: =IF(OR($B$4="Все",data_журнал!$H$7=$B$4),data_журнал!H7,"") -> Закрыто
A13: =IF(OR($B$4="Все",data_журнал!$H$8=$B$4),data_журнал!A8,"") -> BR-007 | B13: =IF(OR($B$4="Все",data_журнал!$H$8=$B$4),data_журнал!B8,"") -> 46272 | C13: =IF(OR($B$4="Все",data_журнал!$H$8=$B$4),data_журнал!C8,"") -> PSP Gamma | D13: =IF(OR($B$4="Все",data_журнал!$H$8=$B$4),data_журнал!D8,"") -> GAM-0907-0001 | E13: =IF(OR($B$4="Все",data_журнал!$H$8=$B$4),data_журнал!E8,"") -> Сумма | F13: =IF(OR($B$4="Все",data_журнал!$H$8=$B$4),data_журнал!F8,"") -> 1727.97 | G13: =IF(OR($B$4="Все",data_журнал!$H$8=$B$4),data_журнал!G8,"") -> Частичный возврат у PSP не отражён во внутреннем учёте | H13: =IF(OR($B$4="Все",data_журнал!$H$8=$B$4),data_журнал!H8,"") -> Закрыто
A14: =IF(OR($B$4="Все",data_журнал!$H$9=$B$4),data_журнал!A9,"") -> BR-008 | B14: =IF(OR($B$4="Все",data_журнал!$H$9=$B$4),data_журнал!B9,"") -> 46272 | C14: =IF(OR($B$4="Все",data_журнал!$H$9=$B$4),data_журнал!C9,"") -> PSP Gamma | D14: =IF(OR($B$4="Все",data_журнал!$H$9=$B$4),data_журнал!D9,"") -> GAM-0907-0002 | E14: =IF(OR($B$4="Все",data_журнал!$H$9=$B$4),data_журнал!E9,"") -> Комиссия | F14: =IF(OR($B$4="Все",data_журнал!$H$9=$B$4),data_журнал!F9,"") -> 635.96 | G14: =IF(OR($B$4="Все",data_журнал!$H$9=$B$4),data_журнал!G9,"") -> PSP применил старую тарифную сетку | H14: =IF(OR($B$4="Все",data_журнал!$H$9=$B$4),data_журнал!H9,"") -> Закрыто
A15: =IF(OR($B$4="Все",data_журнал!$H$10=$B$4),data_журнал!A10,"") -> BR-009 | B15: =IF(OR($B$4="Все",data_журнал!$H$10=$B$4),data_журнал!B10,"") -> 46273 | C15: =IF(OR($B$4="Все",data_журнал!$H$10=$B$4),data_журнал!C10,"") -> PSP Gamma | D15: =IF(OR($B$4="Все",data_журнал!$H$10=$B$4),data_журнал!D10,"") -> GAM-0908-0000 | E15: =IF(OR($B$4="Все",data_журнал!$H$10=$B$4),data_журнал!E10,"") -> Нет в учёте | F15: =IF(OR($B$4="Все",data_журнал!$H$10=$B$4),data_журнал!F10,"") -> 14693.71 | G15: =IF(OR($B$4="Все",data_журнал!$H$10=$B$4),data_журнал!G10,"") -> Возврат (refund) не загрузился во внутренний учёт | H15: =IF(OR($B$4="Все",data_журнал!$H$10=$B$4),data_журнал!H10,"") -> Закрыто
A16: =IF(OR($B$4="Все",data_журнал!$H$11=$B$4),data_журнал!A11,"") -> BR-010 | B16: =IF(OR($B$4="Все",data_журнал!$H$11=$B$4),data_журнал!B11,"") -> 46274 | C16: =IF(OR($B$4="Все",data_журнал!$H$11=$B$4),data_журнал!C11,"") -> PSP Gamma | D16: =IF(OR($B$4="Все",data_журнал!$H$11=$B$4),data_журнал!D11,"") -> GAM-0909-0000 | E16: =IF(OR($B$4="Все",data_журнал!$H$11=$B$4),data_журнал!E11,"") -> Комиссия | F16: =IF(OR($B$4="Все",data_журнал!$H$11=$B$4),data_журнал!F11,"") -> 352.9 | G16: =IF(OR($B$4="Все",data_журнал!$H$11=$B$4),data_журнал!G11,"") -> PSP применил старую тарифную сетку | H16: =IF(OR($B$4="Все",data_журнал!$H$11=$B$4),data_журнал!H11,"") -> Закрыто
A17: =IF(OR($B$4="Все",data_журнал!$H$12=$B$4),data_журнал!A12,"") -> BR-011 | B17: =IF(OR($B$4="Все",data_журнал!$H$12=$B$4),data_журнал!B12,"") -> 46275 | C17: =IF(OR($B$4="Все",data_журнал!$H$12=$B$4),data_журнал!C12,"") -> PSP Alfa | D17: =IF(OR($B$4="Все",data_журнал!$H$12=$B$4),data_журнал!D12,"") -> ALF-0910-0000 | E17: =IF(OR($B$4="Все",data_журнал!$H$12=$B$4),data_журнал!E12,"") -> Сумма | F17: =IF(OR($B$4="Все",data_журнал!$H$12=$B$4),data_журнал!F12,"") -> 1866.01 | G17: =IF(OR($B$4="Все",data_журнал!$H$12=$B$4),data_журнал!G12,"") -> Частичный возврат у PSP не отражён во внутреннем учёте | H17: =IF(OR($B$4="Все",data_журнал!$H$12=$B$4),data_журнал!H12,"") -> Закрыто
A18: =IF(OR($B$4="Все",data_журнал!$H$13=$B$4),data_журнал!A13,"") -> BR-012 | B18: =IF(OR($B$4="Все",data_журнал!$H$13=$B$4),data_журнал!B13,"") -> 46276 | C18: =IF(OR($B$4="Все",data_журнал!$H$13=$B$4),data_журнал!C13,"") -> PSP Alfa | D18: =IF(OR($B$4="Все",data_журнал!$H$13=$B$4),data_журнал!D13,"") -> ALF-0911-0000 | E18: =IF(OR($B$4="Все",data_журнал!$H$13=$B$4),data_журнал!E13,"") -> Нет в учёте | F18: =IF(OR($B$4="Все",data_журнал!$H$13=$B$4),data_журнал!F13,"") -> 18992.04 | G18: =IF(OR($B$4="Все",data_журнал!$H$13=$B$4),data_журнал!G13,"") -> Возврат (refund) не загрузился во внутренний учёт | H18: =IF(OR($B$4="Все",data_журнал!$H$13=$B$4),data_журнал!H13,"") -> Закрыто
A19: =IF(OR($B$4="Все",data_журнал!$H$14=$B$4),data_журнал!A14,"") -> BR-013 | B19: =IF(OR($B$4="Все",data_журнал!$H$14=$B$4),data_журнал!B14,"") -> 46276 | C19: =IF(OR($B$4="Все",data_журнал!$H$14=$B$4),data_журнал!C14,"") -> PSP Alfa | D19: =IF(OR($B$4="Все",data_журнал!$H$14=$B$4),data_журнал!D14,"") -> ALF-0911-0001 | E19: =IF(OR($B$4="Все",data_журнал!$H$14=$B$4),data_журнал!E14,"") -> Статус | F19: =IF(OR($B$4="Все",data_журнал!$H$14=$B$4),data_журнал!F14,"") -> 20467.64 | G19: =IF(OR($B$4="Все",data_журнал!$H$14=$B$4),data_журнал!G14,"") -> Таймаут: у нас success, у PSP failed — PSP подтвердил позже | H19: =IF(OR($B$4="Все",data_журнал!$H$14=$B$4),data_журнал!H14,"") -> Закрыто
A20: =IF(OR($B$4="Все",data_журнал!$H$15=$B$4),data_журнал!A15,"") -> BR-014 | B20: =IF(OR($B$4="Все",data_журнал!$H$15=$B$4),data_журнал!B15,"") -> 46276 | C20: =IF(OR($B$4="Все",data_журнал!$H$15=$B$4),data_журнал!C15,"") -> PSP Gamma | D20: =IF(OR($B$4="Все",data_журнал!$H$15=$B$4),data_журнал!D15,"") -> GAM-0911-0000 | E20: =IF(OR($B$4="Все",data_журнал!$H$15=$B$4),data_журнал!E15,"") -> Комиссия | F20: =IF(OR($B$4="Все",data_журнал!$H$15=$B$4),data_журнал!F15,"") -> 889.42 | G20: =IF(OR($B$4="Все",data_журнал!$H$15=$B$4),data_журнал!G15,"") -> PSP применил старую тарифную сетку | H20: =IF(OR($B$4="Все",data_журнал!$H$15=$B$4),data_журнал!H15,"") -> Закрыто
A21: =IF(OR($B$4="Все",data_журнал!$H$16=$B$4),data_журнал!A16,"") -> BR-015 | B21: =IF(OR($B$4="Все",data_журнал!$H$16=$B$4),data_журнал!B16,"") -> 46276 | C21: =IF(OR($B$4="Все",data_журнал!$H$16=$B$4),data_журнал!C16,"") -> PSP Gamma | D21: =IF(OR($B$4="Все",data_журнал!$H$16=$B$4),data_журнал!D16,"") -> GAM-0911-0001 | E21: =IF(OR($B$4="Все",data_журнал!$H$16=$B$4),data_журнал!E16,"") -> Нет в учёте | F21: =IF(OR($B$4="Все",data_журнал!$H$16=$B$4),data_журнал!F16,"") -> 5269.25 | G21: =IF(OR($B$4="Все",data_журнал!$H$16=$B$4),data_журнал!G16,"") -> Возврат (refund) не загрузился во внутренний учёт | H21: =IF(OR($B$4="Все",data_журнал!$H$16=$B$4),data_журнал!H16,"") -> Закрыто
A22: =IF(OR($B$4="Все",data_журнал!$H$17=$B$4),data_журнал!A17,"") -> BR-016 | B22: =IF(OR($B$4="Все",data_журнал!$H$17=$B$4),data_журнал!B17,"") -> 46277 | C22: =IF(OR($B$4="Все",data_журнал!$H$17=$B$4),data_журнал!C17,"") -> PSP Gamma | D22: =IF(OR($B$4="Все",data_журнал!$H$17=$B$4),data_журнал!D17,"") -> GAM-0912-0000 | E22: =IF(OR($B$4="Все",data_журнал!$H$17=$B$4),data_журнал!E17,"") -> Сумма | F22: =IF(OR($B$4="Все",data_журнал!$H$17=$B$4),data_журнал!F17,"") -> 2592.94 | G22: =IF(OR($B$4="Все",data_журнал!$H$17=$B$4),data_журнал!G17,"") -> Частичный возврат у PSP не отражён во внутреннем учёте | H22: =IF(OR($B$4="Все",data_журнал!$H$17=$B$4),data_журнал!H17,"") -> Закрыто
A23: =IF(OR($B$4="Все",data_журнал!$H$18=$B$4),data_журнал!A18,"") -> BR-017 | B23: =IF(OR($B$4="Все",data_журнал!$H$18=$B$4),data_журнал!B18,"") -> 46278 | C23: =IF(OR($B$4="Все",data_журнал!$H$18=$B$4),data_журнал!C18,"") -> PSP Gamma | D23: =IF(OR($B$4="Все",data_журнал!$H$18=$B$4),data_журнал!D18,"") -> GAM-0913-0000 | E23: =IF(OR($B$4="Все",data_журнал!$H$18=$B$4),data_журнал!E18,"") -> Нет у PSP | F23: =IF(OR($B$4="Все",data_журнал!$H$18=$B$4),data_журнал!F18,"") -> 13860.2 | G23: =IF(OR($B$4="Все",data_журнал!$H$18=$B$4),data_журнал!G18,"") -> Транзакция попала в выписку следующего дня (cut-off) | H23: =IF(OR($B$4="Все",data_журнал!$H$18=$B$4),data_журнал!H18,"") -> Закрыто
A24: =IF(OR($B$4="Все",data_журнал!$H$19=$B$4),data_журнал!A19,"") -> BR-018 | B24: =IF(OR($B$4="Все",data_журнал!$H$19=$B$4),data_журнал!B19,"") -> 46278 | C24: =IF(OR($B$4="Все",data_журнал!$H$19=$B$4),data_журнал!C19,"") -> PSP Gamma | D24: =IF(OR($B$4="Все",data_журнал!$H$19=$B$4),data_журнал!D19,"") -> GAM-0913-0001 | E24: =IF(OR($B$4="Все",data_журнал!$H$19=$B$4),data_журнал!E19,"") -> Нет у PSP | F24: =IF(OR($B$4="Все",data_журнал!$H$19=$B$4),data_журнал!F19,"") -> 13273.4 | G24: =IF(OR($B$4="Все",data_журнал!$H$19=$B$4),data_журнал!G19,"") -> Транзакция попала в выписку следующего дня (cut-off) | H24: =IF(OR($B$4="Все",data_журнал!$H$19=$B$4),data_журнал!H19,"") -> Закрыто
A25: =IF(OR($B$4="Все",data_журнал!$H$20=$B$4),data_журнал!A20,"") -> BR-019 | B25: =IF(OR($B$4="Все",data_журнал!$H$20=$B$4),data_журнал!B20,"") -> 46279 | C25: =IF(OR($B$4="Все",data_журнал!$H$20=$B$4),data_журнал!C20,"") -> PSP Gamma | D25: =IF(OR($B$4="Все",data_журнал!$H$20=$B$4),data_журнал!D20,"") -> GAM-0914-0000 | E25: =IF(OR($B$4="Все",data_журнал!$H$20=$B$4),data_журнал!E20,"") -> Сумма | F25: =IF(OR($B$4="Все",data_журнал!$H$20=$B$4),data_журнал!F20,"") -> 1385.08 | G25: =IF(OR($B$4="Все",data_журнал!$H$20=$B$4),data_журнал!G20,"") -> Частичный возврат у PSP не отражён во внутреннем учёте | H25: =IF(OR($B$4="Все",data_журнал!$H$20=$B$4),data_журнал!H20,"") -> Закрыто
A26: =IF(OR($B$4="Все",data_журнал!$H$21=$B$4),data_журнал!A21,"") -> BR-020 | B26: =IF(OR($B$4="Все",data_журнал!$H$21=$B$4),data_журнал!B21,"") -> 46279 | C26: =IF(OR($B$4="Все",data_журнал!$H$21=$B$4),data_журнал!C21,"") -> PSP Gamma | D26: =IF(OR($B$4="Все",data_журнал!$H$21=$B$4),data_журнал!D21,"") -> GAM-0914-0001 | E26: =IF(OR($B$4="Все",data_журнал!$H$21=$B$4),data_журнал!E21,"") -> Нет в учёте | F26: =IF(OR($B$4="Все",data_журнал!$H$21=$B$4),data_журнал!F21,"") -> 4159.91 | G26: =IF(OR($B$4="Все",data_журнал!$H$21=$B$4),data_журнал!G21,"") -> Возврат (refund) не загрузился во внутренний учёт | H26: =IF(OR($B$4="Все",data_журнал!$H$21=$B$4),data_журнал!H21,"") -> Закрыто
A27: =IF(OR($B$4="Все",data_журнал!$H$22=$B$4),data_журнал!A22,"") -> BR-021 | B27: =IF(OR($B$4="Все",data_журнал!$H$22=$B$4),data_журнал!B22,"") -> 46280 | C27: =IF(OR($B$4="Все",data_журнал!$H$22=$B$4),data_журнал!C22,"") -> PSP Gamma | D27: =IF(OR($B$4="Все",data_журнал!$H$22=$B$4),data_журнал!D22,"") -> GAM-0915-0000 | E27: =IF(OR($B$4="Все",data_журнал!$H$22=$B$4),data_журнал!E22,"") -> Сумма | F27: =IF(OR($B$4="Все",data_журнал!$H$22=$B$4),data_журнал!F22,"") -> 1419.52 | G27: =IF(OR($B$4="Все",data_журнал!$H$22=$B$4),data_журнал!G22,"") -> Частичный возврат у PSP не отражён во внутреннем учёте | H27: =IF(OR($B$4="Все",data_журнал!$H$22=$B$4),data_журнал!H22,"") -> Закрыто
A28: =IF(OR($B$4="Все",data_журнал!$H$23=$B$4),data_журнал!A23,"") -> BR-022 | B28: =IF(OR($B$4="Все",data_журнал!$H$23=$B$4),data_журнал!B23,"") -> 46280 | C28: =IF(OR($B$4="Все",data_журнал!$H$23=$B$4),data_журнал!C23,"") -> PSP Gamma | D28: =IF(OR($B$4="Все",data_журнал!$H$23=$B$4),data_журнал!D23,"") -> GAM-0915-0001 | E28: =IF(OR($B$4="Все",data_журнал!$H$23=$B$4),data_журнал!E23,"") -> Комиссия | F28: =IF(OR($B$4="Все",data_журнал!$H$23=$B$4),data_журнал!F23,"") -> 391.21 | G28: =IF(OR($B$4="Все",data_журнал!$H$23=$B$4),data_журнал!G23,"") -> PSP применил старую тарифную сетку | H28: =IF(OR($B$4="Все",data_журнал!$H$23=$B$4),data_журнал!H23,"") -> Закрыто
A29: =IF(OR($B$4="Все",data_журнал!$H$24=$B$4),data_журнал!A24,"") -> BR-023 | B29: =IF(OR($B$4="Все",data_журнал!$H$24=$B$4),data_журнал!B24,"") -> 46280 | C29: =IF(OR($B$4="Все",data_журнал!$H$24=$B$4),data_журнал!C24,"") -> PSP Gamma | D29: =IF(OR($B$4="Все",data_журнал!$H$24=$B$4),data_журнал!D24,"") -> GAM-0915-0002 | E29: =IF(OR($B$4="Все",data_журнал!$H$24=$B$4),data_журнал!E24,"") -> Комиссия | F29: =IF(OR($B$4="Все",data_журнал!$H$24=$B$4),data_журнал!F24,"") -> 721.8 | G29: =IF(OR($B$4="Все",data_журнал!$H$24=$B$4),data_журнал!G24,"") -> PSP применил старую тарифную сетку | H29: =IF(OR($B$4="Все",data_журнал!$H$24=$B$4),data_журнал!H24,"") -> Закрыто
A30: =IF(OR($B$4="Все",data_журнал!$H$25=$B$4),data_журнал!A25,"") -> BR-024 | B30: =IF(OR($B$4="Все",data_журнал!$H$25=$B$4),data_журнал!B25,"") -> 46280 | C30: =IF(OR($B$4="Все",data_журнал!$H$25=$B$4),data_журнал!C25,"") -> PSP Gamma | D30: =IF(OR($B$4="Все",data_журнал!$H$25=$B$4),data_журнал!D25,"") -> GAM-0915-0003 | E30: =IF(OR($B$4="Все",data_журнал!$H$25=$B$4),data_журнал!E25,"") -> Сумма | F30: =IF(OR($B$4="Все",data_журнал!$H$25=$B$4),data_журнал!F25,"") -> 332.32 | G30: =IF(OR($B$4="Все",data_журнал!$H$25=$B$4),data_журнал!G25,"") -> Частичный возврат у PSP не отражён во внутреннем учёте | H30: =IF(OR($B$4="Все",data_журнал!$H$25=$B$4),data_журнал!H25,"") -> Закрыто
A31: =IF(OR($B$4="Все",data_журнал!$H$26=$B$4),data_журнал!A26,"") -> BR-025 | B31: =IF(OR($B$4="Все",data_журнал!$H$26=$B$4),data_журнал!B26,"") -> 46280 | C31: =IF(OR($B$4="Все",data_журнал!$H$26=$B$4),data_журнал!C26,"") -> PSP Gamma | D31: =IF(OR($B$4="Все",data_журнал!$H$26=$B$4),data_журнал!D26,"") -> GAM-0915-0004 | E31: =IF(OR($B$4="Все",data_журнал!$H$26=$B$4),data_журнал!E26,"") -> Сумма | F31: =IF(OR($B$4="Все",data_журнал!$H$26=$B$4),data_журнал!F26,"") -> 2681.83 | G31: =IF(OR($B$4="Все",data_журнал!$H$26=$B$4),data_журнал!G26,"") -> Частичный возврат у PSP не отражён во внутреннем учёте | H31: =IF(OR($B$4="Все",data_журнал!$H$26=$B$4),data_журнал!H26,"") -> Закрыто
A32: =IF(OR($B$4="Все",data_журнал!$H$27=$B$4),data_журнал!A27,"") -> BR-026 | B32: =IF(OR($B$4="Все",data_журнал!$H$27=$B$4),data_журнал!B27,"") -> 46281 | C32: =IF(OR($B$4="Все",data_журнал!$H$27=$B$4),data_журнал!C27,"") -> PSP Beta | D32: =IF(OR($B$4="Все",data_журнал!$H$27=$B$4),data_журнал!D27,"") -> BET-0916-0000 | E32: =IF(OR($B$4="Все",data_журнал!$H$27=$B$4),data_журнал!E27,"") -> Статус | F32: =IF(OR($B$4="Все",data_журнал!$H$27=$B$4),data_журнал!F27,"") -> 29215.29 | G32: =IF(OR($B$4="Все",data_журнал!$H$27=$B$4),data_журнал!G27,"") -> Таймаут: у нас success, у PSP failed — PSP подтвердил позже | H32: =IF(OR($B$4="Все",data_журнал!$H$27=$B$4),data_журнал!H27,"") -> Закрыто
A33: =IF(OR($B$4="Все",data_журнал!$H$28=$B$4),data_журнал!A28,"") -> BR-027 | B33: =IF(OR($B$4="Все",data_журнал!$H$28=$B$4),data_журнал!B28,"") -> 46281 | C33: =IF(OR($B$4="Все",data_журнал!$H$28=$B$4),data_журнал!C28,"") -> PSP Beta | D33: =IF(OR($B$4="Все",data_журнал!$H$28=$B$4),data_журнал!D28,"") -> BET-0916-0001 | E33: =IF(OR($B$4="Все",data_журнал!$H$28=$B$4),data_журнал!E28,"") -> Статус | F33: =IF(OR($B$4="Все",data_журнал!$H$28=$B$4),data_журнал!F28,"") -> 30570.85 | G33: =IF(OR($B$4="Все",data_журнал!$H$28=$B$4),data_журнал!G28,"") -> Таймаут: у нас success, у PSP failed — PSP подтвердил позже | H33: =IF(OR($B$4="Все",data_журнал!$H$28=$B$4),data_журнал!H28,"") -> Закрыто
A34: =IF(OR($B$4="Все",data_журнал!$H$29=$B$4),data_журнал!A29,"") -> BR-028 | B34: =IF(OR($B$4="Все",data_журнал!$H$29=$B$4),data_журнал!B29,"") -> 46281 | C34: =IF(OR($B$4="Все",data_журнал!$H$29=$B$4),data_журнал!C29,"") -> PSP Gamma | D34: =IF(OR($B$4="Все",data_журнал!$H$29=$B$4),data_журнал!D29,"") -> GAM-0916-0000 | E34: =IF(OR($B$4="Все",data_журнал!$H$29=$B$4),data_журнал!E29,"") -> Сумма | F34: =IF(OR($B$4="Все",data_журнал!$H$29=$B$4),data_журнал!F29,"") -> 2654.51 | G34: =IF(OR($B$4="Все",data_журнал!$H$29=$B$4),data_журнал!G29,"") -> Частичный возврат у PSP не отражён во внутреннем учёте | H34: =IF(OR($B$4="Все",data_журнал!$H$29=$B$4),data_журнал!H29,"") -> Закрыто
A35: =IF(OR($B$4="Все",data_журнал!$H$30=$B$4),data_журнал!A30,"") -> BR-029 | B35: =IF(OR($B$4="Все",data_журнал!$H$30=$B$4),data_журнал!B30,"") -> 46281 | C35: =IF(OR($B$4="Все",data_журнал!$H$30=$B$4),data_журнал!C30,"") -> PSP Gamma | D35: =IF(OR($B$4="Все",data_журнал!$H$30=$B$4),data_журнал!D30,"") -> GAM-0916-0001 | E35: =IF(OR($B$4="Все",data_журнал!$H$30=$B$4),data_журнал!E30,"") -> Нет в учёте | F35: =IF(OR($B$4="Все",data_журнал!$H$30=$B$4),data_журнал!F30,"") -> 1148.64 | G35: =IF(OR($B$4="Все",data_журнал!$H$30=$B$4),data_журнал!G30,"") -> Возврат (refund) не загрузился во внутренний учёт | H35: =IF(OR($B$4="Все",data_журнал!$H$30=$B$4),data_журнал!H30,"") -> Закрыто
A36: =IF(OR($B$4="Все",data_журнал!$H$31=$B$4),data_журнал!A31,"") -> BR-030 | B36: =IF(OR($B$4="Все",data_журнал!$H$31=$B$4),data_журнал!B31,"") -> 46282 | C36: =IF(OR($B$4="Все",data_журнал!$H$31=$B$4),data_журнал!C31,"") -> PSP Beta | D36: =IF(OR($B$4="Все",data_журнал!$H$31=$B$4),data_журнал!D31,"") -> BET-0917-0000 | E36: =IF(OR($B$4="Все",data_журнал!$H$31=$B$4),data_журнал!E31,"") -> Статус | F36: =IF(OR($B$4="Все",data_журнал!$H$31=$B$4),data_журнал!F31,"") -> 6386.29 | G36: =IF(OR($B$4="Все",data_журнал!$H$31=$B$4),data_журнал!G31,"") -> Таймаут: у нас success, у PSP failed — PSP подтвердил позже | H36: =IF(OR($B$4="Все",data_журнал!$H$31=$B$4),data_журнал!H31,"") -> Закрыто
A37: =IF(OR($B$4="Все",data_журнал!$H$32=$B$4),data_журнал!A32,"") -> BR-031 | B37: =IF(OR($B$4="Все",data_журнал!$H$32=$B$4),data_журнал!B32,"") -> 46282 | C37: =IF(OR($B$4="Все",data_журнал!$H$32=$B$4),data_журнал!C32,"") -> PSP Beta | D37: =IF(OR($B$4="Все",data_журнал!$H$32=$B$4),data_журнал!D32,"") -> BET-0917-0001 | E37: =IF(OR($B$4="Все",data_журнал!$H$32=$B$4),data_журнал!E32,"") -> Нет у PSP | F37: =IF(OR($B$4="Все",data_журнал!$H$32=$B$4),data_журнал!F32,"") -> 15678.89 | G37: =IF(OR($B$4="Все",data_журнал!$H$32=$B$4),data_журнал!G32,"") -> Транзакция попала в выписку следующего дня (cut-off) | H37: =IF(OR($B$4="Все",data_журнал!$H$32=$B$4),data_журнал!H32,"") -> Закрыто
A38: =IF(OR($B$4="Все",data_журнал!$H$33=$B$4),data_журнал!A33,"") -> BR-032 | B38: =IF(OR($B$4="Все",data_журнал!$H$33=$B$4),data_журнал!B33,"") -> 46282 | C38: =IF(OR($B$4="Все",data_журнал!$H$33=$B$4),data_журнал!C33,"") -> PSP Gamma | D38: =IF(OR($B$4="Все",data_журнал!$H$33=$B$4),data_журнал!D33,"") -> GAM-0917-0000 | E38: =IF(OR($B$4="Все",data_журнал!$H$33=$B$4),data_журнал!E33,"") -> Комиссия | F38: =IF(OR($B$4="Все",data_журнал!$H$33=$B$4),data_журнал!F33,"") -> 936.79 | G38: =IF(OR($B$4="Все",data_журнал!$H$33=$B$4),data_журнал!G33,"") -> PSP применил старую тарифную сетку | H38: =IF(OR($B$4="Все",data_журнал!$H$33=$B$4),data_журнал!H33,"") -> Закрыто
A39: =IF(OR($B$4="Все",data_журнал!$H$34=$B$4),data_журнал!A34,"") -> BR-033 | B39: =IF(OR($B$4="Все",data_журнал!$H$34=$B$4),data_журнал!B34,"") -> 46282 | C39: =IF(OR($B$4="Все",data_журнал!$H$34=$B$4),data_журнал!C34,"") -> PSP Gamma | D39: =IF(OR($B$4="Все",data_журнал!$H$34=$B$4),data_журнал!D34,"") -> GAM-0917-0001 | E39: =IF(OR($B$4="Все",data_журнал!$H$34=$B$4),data_журнал!E34,"") -> Нет у PSP | F39: =IF(OR($B$4="Все",data_журнал!$H$34=$B$4),data_журнал!F34,"") -> 4106.83 | G39: =IF(OR($B$4="Все",data_журнал!$H$34=$B$4),data_журнал!G34,"") -> Транзакция попала в выписку следующего дня (cut-off) | H39: =IF(OR($B$4="Все",data_журнал!$H$34=$B$4),data_журнал!H34,"") -> Закрыто
A40: =IF(OR($B$4="Все",data_журнал!$H$35=$B$4),data_журнал!A35,"") -> BR-034 | B40: =IF(OR($B$4="Все",data_журнал!$H$35=$B$4),data_журнал!B35,"") -> 46284 | C40: =IF(OR($B$4="Все",data_журнал!$H$35=$B$4),data_журнал!C35,"") -> PSP Alfa | D40: =IF(OR($B$4="Все",data_журнал!$H$35=$B$4),data_журнал!D35,"") -> ALF-0919-0000 | E40: =IF(OR($B$4="Все",data_журнал!$H$35=$B$4),data_журнал!E35,"") -> Нет у PSP | F40: =IF(OR($B$4="Все",data_журнал!$H$35=$B$4),data_журнал!F35,"") -> 8986.83 | G40: =IF(OR($B$4="Все",data_журнал!$H$35=$B$4),data_журнал!G35,"") -> Транзакция попала в выписку следующего дня (cut-off) | H40: =IF(OR($B$4="Все",data_журнал!$H$35=$B$4),data_журнал!H35,"") -> Закрыто
A41: =IF(OR($B$4="Все",data_журнал!$H$36=$B$4),data_журнал!A36,"") -> BR-035 | B41: =IF(OR($B$4="Все",data_журнал!$H$36=$B$4),data_журнал!B36,"") -> 46284 | C41: =IF(OR($B$4="Все",data_журнал!$H$36=$B$4),data_журнал!C36,"") -> PSP Beta | D41: =IF(OR($B$4="Все",data_журнал!$H$36=$B$4),data_журнал!D36,"") -> BET-0919-0000 | E41: =IF(OR($B$4="Все",data_журнал!$H$36=$B$4),data_журнал!E36,"") -> Сумма | F41: =IF(OR($B$4="Все",data_журнал!$H$36=$B$4),data_журнал!F36,"") -> 548.2 | G41: =IF(OR($B$4="Все",data_журнал!$H$36=$B$4),data_журнал!G36,"") -> Частичный возврат у PSP не отражён во внутреннем учёте | H41: =IF(OR($B$4="Все",data_журнал!$H$36=$B$4),data_журнал!H36,"") -> Закрыто
A42: =IF(OR($B$4="Все",data_журнал!$H$37=$B$4),data_журнал!A37,"") -> BR-036 | B42: =IF(OR($B$4="Все",data_журнал!$H$37=$B$4),data_журнал!B37,"") -> 46284 | C42: =IF(OR($B$4="Все",data_журнал!$H$37=$B$4),data_журнал!C37,"") -> PSP Gamma | D42: =IF(OR($B$4="Все",data_журнал!$H$37=$B$4),data_журнал!D37,"") -> GAM-0919-0000 | E42: =IF(OR($B$4="Все",data_журнал!$H$37=$B$4),data_журнал!E37,"") -> Статус | F42: =IF(OR($B$4="Все",data_журнал!$H$37=$B$4),data_журнал!F37,"") -> 29989.45 | G42: =IF(OR($B$4="Все",data_журнал!$H$37=$B$4),data_журнал!G37,"") -> Таймаут: у нас success, у PSP failed — PSP подтвердил позже | H42: =IF(OR($B$4="Все",data_журнал!$H$37=$B$4),data_журнал!H37,"") -> Закрыто
...

Sheet Балансы
A1: Контроль балансов на счетах PSP
A2: Дельта = фактический баланс из выписки PSP − ожидаемый по учёту (остаток + депозиты − выводы − комиссии)
A4: Порог эскалации, ₽: | B4: 50000 | C4: Окно тренда, дней: | D4: 7
A6: Дата | B6: PSP Alfa, дельта | C6: PSP Beta, дельта | D6: PSP Gamma, дельта | F6: Сводка | G6: PSP Alfa | H6: PSP Beta | I6: PSP Gamma
A7: 46266 | B7: =SUMIFS(data_балансы!$D$2:$D$91,data_балансы!$A$2:$A$91,$A7,data_балансы!$B$2:$B$91,"PSP Alfa")-SUMIFS(data_балансы!$C$2:$C$91,data_балансы!$A$2:$A$91,$A7,data_балансы!$B$2:$B$91,"PSP Alfa") -> -3626.22 | C7: =SUMIFS(data_балансы!$D$2:$D$91,data_балансы!$A$2:$A$91,$A7,data_балансы!$B$2:$B$91,"PSP Beta")-SUMIFS(data_балансы!$C$2:$C$91,data_балансы!$A$2:$A$91,$A7,data_балансы!$B$2:$B$91,"PSP Beta") -> -6897.52 | D7: =SUMIFS(data_балансы!$D$2:$D$91,data_балансы!$A$2:$A$91,$A7,data_балансы!$B$2:$B$91,"PSP Gamma")-SUMIFS(data_балансы!$C$2:$C$91,data_балансы!$A$2:$A$91,$A7,data_балансы!$B$2:$B$91,"PSP Gamma") -> -8175.51 | F7: Дельта на конец месяца | G7: =B36 -> -1935.38 | H7: =C36 -> -6510.04 | I7: =D36 -> -46782.67
A8: 46267 | B8: =SUMIFS(data_балансы!$D$2:$D$91,data_балансы!$A$2:$A$91,$A8,data_балансы!$B$2:$B$91,"PSP Alfa")-SUMIFS(data_балансы!$C$2:$C$91,data_балансы!$A$2:$A$91,$A8,data_балансы!$B$2:$B$91,"PSP Alfa") -> 9957.73 | C8: =SUMIFS(data_балансы!$D$2:$D$91,data_балансы!$A$2:$A$91,$A8,data_балансы!$B$2:$B$91,"PSP Beta")-SUMIFS(data_балансы!$C$2:$C$91,data_балансы!$A$2:$A$91,$A8,data_балансы!$B$2:$B$91,"PSP Beta") -> 1145.19 | D8: =SUMIFS(data_балансы!$D$2:$D$91,data_балансы!$A$2:$A$91,$A8,data_балансы!$B$2:$B$91,"PSP Gamma")-SUMIFS(data_балансы!$C$2:$C$91,data_балансы!$A$2:$A$91,$A8,data_балансы!$B$2:$B$91,"PSP Gamma") -> -14575.55 | F8: Минимум дельты | G8: =MIN(B7:B36) -> -14229.65 | H8: =MIN(C7:C36) -> -98636.4 | I8: =MIN(D7:D36) -> -57379.06
A9: 46268 | B9: =SUMIFS(data_балансы!$D$2:$D$91,data_балансы!$A$2:$A$91,$A9,data_балансы!$B$2:$B$91,"PSP Alfa")-SUMIFS(data_балансы!$C$2:$C$91,data_балансы!$A$2:$A$91,$A9,data_балансы!$B$2:$B$91,"PSP Alfa") -> -12542.81 | C9: =SUMIFS(data_балансы!$D$2:$D$91,data_балансы!$A$2:$A$91,$A9,data_балансы!$B$2:$B$91,"PSP Beta")-SUMIFS(data_балансы!$C$2:$C$91,data_балансы!$A$2:$A$91,$A9,data_балансы!$B$2:$B$91,"PSP Beta") -> -1932.77 | D9: =SUMIFS(data_балансы!$D$2:$D$91,data_балансы!$A$2:$A$91,$A9,data_балансы!$B$2:$B$91,"PSP Gamma")-SUMIFS(data_балансы!$C$2:$C$91,data_балансы!$A$2:$A$91,$A9,data_балансы!$B$2:$B$91,"PSP Gamma") -> -6770.66 | F9: Дней выше порога | G9: =COUNTIF(B7:B36,">"&$B$4)+COUNTIF(B7:B36,"<"&-$B$4) -> 0 | H9: =COUNTIF(C7:C36,">"&$B$4)+COUNTIF(C7:C36,"<"&-$B$4) -> 2 | I9: =COUNTIF(D7:D36,">"&$B$4)+COUNTIF(D7:D36,"<"&-$B$4) -> 3
A10: 46269 | B10: =SUMIFS(data_балансы!$D$2:$D$91,data_балансы!$A$2:$A$91,$A10,data_балансы!$B$2:$B$91,"PSP Alfa")-SUMIFS(data_балансы!$C$2:$C$91,data_балансы!$A$2:$A$91,$A10,data_балансы!$B$2:$B$91,"PSP Alfa") -> 1182.58 | C10: =SUMIFS(data_балансы!$D$2:$D$91,data_балансы!$A$2:$A$91,$A10,data_балансы!$B$2:$B$91,"PSP Beta")-SUMIFS(data_балансы!$C$2:$C$91,data_балансы!$A$2:$A$91,$A10,data_балансы!$B$2:$B$91,"PSP Beta") -> -6948.14 | D10: =SUMIFS(data_балансы!$D$2:$D$91,data_балансы!$A$2:$A$91,$A10,data_балансы!$B$2:$B$91,"PSP Gamma")-SUMIFS(data_балансы!$C$2:$C$91,data_балансы!$A$2:$A$91,$A10,data_балансы!$B$2:$B$91,"PSP Gamma") -> 1600.77 | F10: Дней, когда дельта ниже вчерашней | G10: =SUMPRODUCT(--(B8:B36<B7:B35)) -> 16 | H10: =SUMPRODUCT(--(C8:C36<C7:C35)) -> 16 | I10: =SUMPRODUCT(--(D8:D36<D7:D35)) -> 14
A11: 46270 | B11: =SUMIFS(data_балансы!$D$2:$D$91,data_балансы!$A$2:$A$91,$A11,data_балансы!$B$2:$B$91,"PSP Alfa")-SUMIFS(data_балансы!$C$2:$C$91,data_балансы!$A$2:$A$91,$A11,data_балансы!$B$2:$B$91,"PSP Alfa") -> -4501.18 | C11: =SUMIFS(data_балансы!$D$2:$D$91,data_балансы!$A$2:$A$91,$A11,data_балансы!$B$2:$B$91,"PSP Beta")-SUMIFS(data_балансы!$C$2:$C$91,data_балансы!$A$2:$A$91,$A11,data_балансы!$B$2:$B$91,"PSP Beta") -> 9921.93 | D11: =SUMIFS(data_балансы!$D$2:$D$91,data_балансы!$A$2:$A$91,$A11,data_балансы!$B$2:$B$91,"PSP Gamma")-SUMIFS(data_балансы!$C$2:$C$91,data_балансы!$A$2:$A$91,$A11,data_балансы!$B$2:$B$91,"PSP Gamma") -> -11211.62
A12: 46271 | B12: =SUMIFS(data_балансы!$D$2:$D$91,data_балансы!$A$2:$A$91,$A12,data_балансы!$B$2:$B$91,"PSP Alfa")-SUMIFS(data_балансы!$C$2:$C$91,data_балансы!$A$2:$A$91,$A12,data_балансы!$B$2:$B$91,"PSP Alfa") -> 8436.99 | C12: =SUMIFS(data_балансы!$D$2:$D$91,data_балансы!$A$2:$A$91,$A12,data_балансы!$B$2:$B$91,"PSP Beta")-SUMIFS(data_балансы!$C$2:$C$91,data_балансы!$A$2:$A$91,$A12,data_балансы!$B$2:$B$91,"PSP Beta") -> 11448.93 | D12: =SUMIFS(data_балансы!$D$2:$D$91,data_балансы!$A$2:$A$91,$A12,data_балансы!$B$2:$B$91,"PSP Gamma")-SUMIFS(data_балансы!$C$2:$C$91,data_балансы!$A$2:$A$91,$A12,data_балансы!$B$2:$B$91,"PSP Gamma") -> -273.64 | F12: Тренд | G12: PSP Alfa | H12: PSP Beta | I12: PSP Gamma
A13: 46272 | B13: =SUMIFS(data_балансы!$D$2:$D$91,data_балансы!$A$2:$A$91,$A13,data_балансы!$B$2:$B$91,"PSP Alfa")-SUMIFS(data_балансы!$C$2:$C$91,data_балансы!$A$2:$A$91,$A13,data_балансы!$B$2:$B$91,"PSP Alfa") -> 7627 | C13: =SUMIFS(data_балансы!$D$2:$D$91,data_балансы!$A$2:$A$91,$A13,data_балансы!$B$2:$B$91,"PSP Beta")-SUMIFS(data_балансы!$C$2:$C$91,data_балансы!$A$2:$A$91,$A13,data_балансы!$B$2:$B$91,"PSP Beta") -> -1058.74 | D13: =SUMIFS(data_балансы!$D$2:$D$91,data_балансы!$A$2:$A$91,$A13,data_балансы!$B$2:$B$91,"PSP Gamma")-SUMIFS(data_балансы!$C$2:$C$91,data_балансы!$A$2:$A$91,$A13,data_балансы!$B$2:$B$91,"PSP Gamma") -> 2221.93 | F13: Средняя дельта, последнее окно | G13: =AVERAGE(OFFSET(B36,-$D$4+1,0,$D$4,1)) -> 2598.5114 | H13: =AVERAGE(OFFSET(C36,-$D$4+1,0,$D$4,1)) -> -2533.69 | I13: =AVERAGE(OFFSET(D36,-$D$4+1,0,$D$4,1)) -> -50890.93
A14: 46273 | B14: =SUMIFS(data_балансы!$D$2:$D$91,data_балансы!$A$2:$A$91,$A14,data_балансы!$B$2:$B$91,"PSP Alfa")-SUMIFS(data_балансы!$C$2:$C$91,data_балансы!$A$2:$A$91,$A14,data_балансы!$B$2:$B$91,"PSP Alfa") -> -9019.18 | C14: =SUMIFS(data_балансы!$D$2:$D$91,data_балансы!$A$2:$A$91,$A14,data_балансы!$B$2:$B$91,"PSP Beta")-SUMIFS(data_балансы!$C$2:$C$91,data_балансы!$A$2:$A$91,$A14,data_балансы!$B$2:$B$91,"PSP Beta") -> -3630.32 | D14: =SUMIFS(data_балансы!$D$2:$D$91,data_балансы!$A$2:$A$91,$A14,data_балансы!$B$2:$B$91,"PSP Gamma")-SUMIFS(data_балансы!$C$2:$C$91,data_балансы!$A$2:$A$91,$A14,data_балансы!$B$2:$B$91,"PSP Gamma") -> -1785.94 | F14: Средняя дельта, предыдущее окно | G14: =AVERAGE(OFFSET(B36,-2*$D$4+1,0,$D$4,1)) -> 2717.0486 | H14: =AVERAGE(OFFSET(C36,-2*$D$4+1,0,$D$4,1)) -> 1443.9857 | I14: =AVERAGE(OFFSET(D36,-2*$D$4+1,0,$D$4,1)) -> -24028.596
A15: 46274 | B15: =SUMIFS(data_балансы!$D$2:$D$91,data_балансы!$A$2:$A$91,$A15,data_балансы!$B$2:$B$91,"PSP Alfa")-SUMIFS(data_балансы!$C$2:$C$91,data_балансы!$A$2:$A$91,$A15,data_балансы!$B$2:$B$91,"PSP Alfa") -> -10428.53 | C15: =SUMIFS(data_балансы!$D$2:$D$91,data_балансы!$A$2:$A$91,$A15,data_балансы!$B$2:$B$91,"PSP Beta")-SUMIFS(data_балансы!$C$2:$C$91,data_балансы!$A$2:$A$91,$A15,data_балансы!$B$2:$B$91,"PSP Beta") -> -79471.41 | D15: =SUMIFS(data_балансы!$D$2:$D$91,data_балансы!$A$2:$A$91,$A15,data_балансы!$B$2:$B$91,"PSP Gamma")-SUMIFS(data_балансы!$C$2:$C$91,data_балансы!$A$2:$A$91,$A15,data_балансы!$B$2:$B$91,"PSP Gamma") -> -13458.7 | F15: Сигнал | G15: =IF(AND(G13<G14,ABS(G13)>$B$4/2),"Проверить","Норма") -> Норма | H15: =IF(AND(H13<H14,ABS(H13)>$B$4/2),"Проверить","Норма") -> Норма | I15: =IF(AND(I13<I14,ABS(I13)>$B$4/2),"Проверить","Норма") -> Проверить
A16: 46275 | B16: =SUMIFS(data_балансы!$D$2:$D$91,data_балансы!$A$2:$A$91,$A16,data_балансы!$B$2:$B$91,"PSP Alfa")-SUMIFS(data_балансы!$C$2:$C$91,data_балансы!$A$2:$A$91,$A16,data_балансы!$B$2:$B$91,"PSP Alfa") -> 5083.76 | C16: =SUMIFS(data_балансы!$D$2:$D$91,data_балансы!$A$2:$A$91,$A16,data_балансы!$B$2:$B$91,"PSP Beta")-SUMIFS(data_балансы!$C$2:$C$91,data_балансы!$A$2:$A$91,$A16,data_балансы!$B$2:$B$91,"PSP Beta") -> -98636.4 | D16: =SUMIFS(data_балансы!$D$2:$D$91,data_балансы!$A$2:$A$91,$A16,data_балансы!$B$2:$B$91,"PSP Gamma")-SUMIFS(data_балансы!$C$2:$C$91,data_балансы!$A$2:$A$91,$A16,data_балансы!$B$2:$B$91,"PSP Gamma") -> -668.12
A17: 46276 | B17: =SUMIFS(data_балансы!$D$2:$D$91,data_балансы!$A$2:$A$91,$A17,data_балансы!$B$2:$B$91,"PSP Alfa")-SUMIFS(data_балансы!$C$2:$C$91,data_балансы!$A$2:$A$91,$A17,data_балансы!$B$2:$B$91,"PSP Alfa") -> -8461.06 | C17: =SUMIFS(data_балансы!$D$2:$D$91,data_балансы!$A$2:$A$91,$A17,data_балансы!$B$2:$B$91,"PSP Beta")-SUMIFS(data_балансы!$C$2:$C$91,data_балансы!$A$2:$A$91,$A17,data_балансы!$B$2:$B$91,"PSP Beta") -> -4789.83 | D17: =SUMIFS(data_балансы!$D$2:$D$91,data_балансы!$A$2:$A$91,$A17,data_балансы!$B$2:$B$91,"PSP Gamma")-SUMIFS(data_балансы!$C$2:$C$91,data_балансы!$A$2:$A$91,$A17,data_балансы!$B$2:$B$91,"PSP Gamma") -> -2978.78
A18: 46277 | B18: =SUMIFS(data_балансы!$D$2:$D$91,data_балансы!$A$2:$A$91,$A18,data_балансы!$B$2:$B$91,"PSP Alfa")-SUMIFS(data_балансы!$C$2:$C$91,data_балансы!$A$2:$A$91,$A18,data_балансы!$B$2:$B$91,"PSP Alfa") -> 8006.94 | C18: =SUMIFS(data_балансы!$D$2:$D$91,data_балансы!$A$2:$A$91,$A18,data_балансы!$B$2:$B$91,"PSP Beta")-SUMIFS(data_балансы!$C$2:$C$91,data_балансы!$A$2:$A$91,$A18,data_балансы!$B$2:$B$91,"PSP Beta") -> 6035.51 | D18: =SUMIFS(data_балансы!$D$2:$D$91,data_балансы!$A$2:$A$91,$A18,data_балансы!$B$2:$B$91,"PSP Gamma")-SUMIFS(data_балансы!$C$2:$C$91,data_балансы!$A$2:$A$91,$A18,data_балансы!$B$2:$B$91,"PSP Gamma") -> 3883.37
A19: 46278 | B19: =SUMIFS(data_балансы!$D$2:$D$91,data_балансы!$A$2:$A$91,$A19,data_балансы!$B$2:$B$91,"PSP Alfa")-SUMIFS(data_балансы!$C$2:$C$91,data_балансы!$A$2:$A$91,$A19,data_балансы!$B$2:$B$91,"PSP Alfa") -> 3217.43 | C19: =SUMIFS(data_балансы!$D$2:$D$91,data_балансы!$A$2:$A$91,$A19,data_балансы!$B$2:$B$91,"PSP Beta")-SUMIFS(data_балансы!$C$2:$C$91,data_балансы!$A$2:$A$91,$A19,data_балансы!$B$2:$B$91,"PSP Beta") -> -14695.46 | D19: =SUMIFS(data_балансы!$D$2:$D$91,data_балансы!$A$2:$A$91,$A19,data_балансы!$B$2:$B$91,"PSP Gamma")-SUMIFS(data_балансы!$C$2:$C$91,data_балансы!$A$2:$A$91,$A19,data_балансы!$B$2:$B$91,"PSP Gamma") -> -10524.08
A20: 46279 | B20: =SUMIFS(data_балансы!$D$2:$D$91,data_балансы!$A$2:$A$91,$A20,data_балансы!$B$2:$B$91,"PSP Alfa")-SUMIFS(data_балансы!$C$2:$C$91,data_балансы!$A$2:$A$91,$A20,data_балансы!$B$2:$B$91,"PSP Alfa") -> -11564.02 | C20: =SUMIFS(data_балансы!$D$2:$D$91,data_балансы!$A$2:$A$91,$A20,data_балансы!$B$2:$B$91,"PSP Beta")-SUMIFS(data_балансы!$C$2:$C$91,data_балансы!$A$2:$A$91,$A20,data_балансы!$B$2:$B$91,"PSP Beta") -> -12431.61 | D20: =SUMIFS(data_балансы!$D$2:$D$91,data_балансы!$A$2:$A$91,$A20,data_балансы!$B$2:$B$91,"PSP Gamma")-SUMIFS(data_балансы!$C$2:$C$91,data_балансы!$A$2:$A$91,$A20,data_балансы!$B$2:$B$91,"PSP Gamma") -> -9384.93
A21: 46280 | B21: =SUMIFS(data_балансы!$D$2:$D$91,data_балансы!$A$2:$A$91,$A21,data_балансы!$B$2:$B$91,"PSP Alfa")-SUMIFS(data_балансы!$C$2:$C$91,data_балансы!$A$2:$A$91,$A21,data_балансы!$B$2:$B$91,"PSP Alfa") -> 13941.62 | C21: =SUMIFS(data_балансы!$D$2:$D$91,data_балансы!$A$2:$A$91,$A21,data_балансы!$B$2:$B$91,"PSP Beta")-SUMIFS(data_балансы!$C$2:$C$91,data_балансы!$A$2:$A$91,$A21,data_балансы!$B$2:$B$91,"PSP Beta") -> -342.66 | D21: =SUMIFS(data_балансы!$D$2:$D$91,data_балансы!$A$2:$A$91,$A21,data_балансы!$B$2:$B$91,"PSP Gamma")-SUMIFS(data_балансы!$C$2:$C$91,data_балансы!$A$2:$A$91,$A21,data_балансы!$B$2:$B$91,"PSP Gamma") -> -18446.46
A22: 46281 | B22: =SUMIFS(data_балансы!$D$2:$D$91,data_балансы!$A$2:$A$91,$A22,data_балансы!$B$2:$B$91,"PSP Alfa")-SUMIFS(data_балансы!$C$2:$C$91,data_балансы!$A$2:$A$91,$A22,data_балансы!$B$2:$B$91,"PSP Alfa") -> -14229.65 | C22: =SUMIFS(data_балансы!$D$2:$D$91,data_балансы!$A$2:$A$91,$A22,data_балансы!$B$2:$B$91,"PSP Beta")-SUMIFS(data_балансы!$C$2:$C$91,data_балансы!$A$2:$A$91,$A22,data_балансы!$B$2:$B$91,"PSP Beta") -> 5718.28 | D22: =SUMIFS(data_балансы!$D$2:$D$91,data_балансы!$A$2:$A$91,$A22,data_балансы!$B$2:$B$91,"PSP Gamma")-SUMIFS(data_балансы!$C$2:$C$91,data_балансы!$A$2:$A$91,$A22,data_балансы!$B$2:$B$91,"PSP Gamma") -> -7310.47
A23: 46282 | B23: =SUMIFS(data_балансы!$D$2:$D$91,data_балансы!$A$2:$A$91,$A23,data_балансы!$B$2:$B$91,"PSP Alfa")-SUMIFS(data_балансы!$C$2:$C$91,data_балансы!$A$2:$A$91,$A23,data_балансы!$B$2:$B$91,"PSP Alfa") -> 5320.42 | C23: =SUMIFS(data_балансы!$D$2:$D$91,data_балансы!$A$2:$A$91,$A23,data_балансы!$B$2:$B$91,"PSP Beta")-SUMIFS(data_балансы!$C$2:$C$91,data_балансы!$A$2:$A$91,$A23,data_балансы!$B$2:$B$91,"PSP Beta") -> -275.36 | D23: =SUMIFS(data_балансы!$D$2:$D$91,data_балансы!$A$2:$A$91,$A23,data_балансы!$B$2:$B$91,"PSP Gamma")-SUMIFS(data_балансы!$C$2:$C$91,data_балансы!$A$2:$A$91,$A23,data_балансы!$B$2:$B$91,"PSP Gamma") -> -22229.39
A24: 46283 | B24: =SUMIFS(data_балансы!$D$2:$D$91,data_балансы!$A$2:$A$91,$A24,data_балансы!$B$2:$B$91,"PSP Alfa")-SUMIFS(data_балансы!$C$2:$C$91,data_балансы!$A$2:$A$91,$A24,data_балансы!$B$2:$B$91,"PSP Alfa") -> -3100.36 | C24: =SUMIFS(data_балансы!$D$2:$D$91,data_балансы!$A$2:$A$91,$A24,data_балансы!$B$2:$B$91,"PSP Beta")-SUMIFS(data_балансы!$C$2:$C$91,data_балансы!$A$2:$A$91,$A24,data_балансы!$B$2:$B$91,"PSP Beta") -> -12208.4 | D24: =SUMIFS(data_балансы!$D$2:$D$91,data_балансы!$A$2:$A$91,$A24,data_балансы!$B$2:$B$91,"PSP Gamma")-SUMIFS(data_балансы!$C$2:$C$91,data_балансы!$A$2:$A$91,$A24,data_балансы!$B$2:$B$91,"PSP Gamma") -> -18984.57
A25: 46284 | B25: =SUMIFS(data_балансы!$D$2:$D$91,data_балансы!$A$2:$A$91,$A25,data_балансы!$B$2:$B$91,"PSP Alfa")-SUMIFS(data_балансы!$C$2:$C$91,data_балансы!$A$2:$A$91,$A25,data_балансы!$B$2:$B$91,"PSP Alfa") -> -12720.1 | C25: =SUMIFS(data_балансы!$D$2:$D$91,data_балансы!$A$2:$A$91,$A25,data_балансы!$B$2:$B$91,"PSP Beta")-SUMIFS(data_балансы!$C$2:$C$91,data_балансы!$A$2:$A$91,$A25,data_балансы!$B$2:$B$91,"PSP Beta") -> 5753.62 | D25: =SUMIFS(data_балансы!$D$2:$D$91,data_балансы!$A$2:$A$91,$A25,data_балансы!$B$2:$B$91,"PSP Gamma")-SUMIFS(data_балансы!$C$2:$C$91,data_балансы!$A$2:$A$91,$A25,data_балансы!$B$2:$B$91,"PSP Gamma") -> -10195
A26: 46285 | B26: =SUMIFS(data_балансы!$D$2:$D$91,data_балансы!$A$2:$A$91,$A26,data_балансы!$B$2:$B$91,"PSP Alfa")-SUMIFS(data_балансы!$C$2:$C$91,data_балансы!$A$2:$A$91,$A26,data_балансы!$B$2:$B$91,"PSP Alfa") -> 3817.28 | C26: =SUMIFS(data_балансы!$D$2:$D$91,data_балансы!$A$2:$A$91,$A26,data_балансы!$B$2:$B$91,"PSP Beta")-SUMIFS(data_балансы!$C$2:$C$91,data_балансы!$A$2:$A$91,$A26,data_балансы!$B$2:$B$91,"PSP Beta") -> 2446.67 | D26: =SUMIFS(data_балансы!$D$2:$D$91,data_балансы!$A$2:$A$91,$A26,data_балансы!$B$2:$B$91,"PSP Gamma")-SUMIFS(data_балансы!$C$2:$C$91,data_балансы!$A$2:$A$91,$A26,data_балансы!$B$2:$B$91,"PSP Gamma") -> -30338.59
A27: 46286 | B27: =SUMIFS(data_балансы!$D$2:$D$91,data_балансы!$A$2:$A$91,$A27,data_балансы!$B$2:$B$91,"PSP Alfa")-SUMIFS(data_балансы!$C$2:$C$91,data_балансы!$A$2:$A$91,$A27,data_балансы!$B$2:$B$91,"PSP Alfa") -> 8174.43 | C27: =SUMIFS(data_балансы!$D$2:$D$91,data_балансы!$A$2:$A$91,$A27,data_балансы!$B$2:$B$91,"PSP Beta")-SUMIFS(data_балансы!$C$2:$C$91,data_балансы!$A$2:$A$91,$A27,data_балансы!$B$2:$B$91,"PSP Beta") -> 927.66 | D27: =SUMIFS(data_балансы!$D$2:$D$91,data_балансы!$A$2:$A$91,$A27,data_балансы!$B$2:$B$91,"PSP Gamma")-SUMIFS(data_балансы!$C$2:$C$91,data_балансы!$A$2:$A$91,$A27,data_балансы!$B$2:$B$91,"PSP Gamma") -> -24711.07
... A36: 46295 | B36: =SUMIFS(data_балансы!$D$2:$D$91,data_балансы!$A$2:$A$91,$A36,data_балансы!$B$2:$B$91,"PSP Alfa")-SUMIFS(data_балансы!$C$2:$C$91,data_балансы!$A$2:$A$91,$A36,data_балансы!$B$2:$B$91,"PSP Alfa") -> -1935.38 | C36: =SUMIFS(data_балансы!$D$2:$D$91,data_балансы!$A$2:$A$91,$A36,data_балансы!$B$2:$B$91,"PSP Beta")-SUMIFS(data_балансы!$C$2:$C$91,data_балансы!$A$2:$A$91,$A36,data_балансы!$B$2:$B$91,"PSP Beta") -> -6510.04 | D36: =SUMIFS(data_балансы!$D$2:$D$91,data_балансы!$A$2:$A$91,$A36,data_балансы!$B$2:$B$91,"PSP Gamma")-SUMIFS(data_балансы!$C$2:$C$91,data_балансы!$A$2:$A$91,$A36,data_балансы!$B$2:$B$91,"PSP Gamma") -> -46782.67

Sheet Платёжный отчёт
A1: Платёжный отчёт для трейдеров и финансов
A2: Сентябрь 2026 · онлайн-букмекер · 3 PSP · Москва, Санкт-Петербург, другие регионы
A4: PSP: | B4: Все
A5: Регион: | B5: Все
A6: Тип операции: | B6: Все
A8: Оборот | B8: Транзакций | C8: Доля успешных | D8: Комиссии | E8: Эффективная комиссия
A9: =SUMIFS(data_платежи!$H$2:$H$73,data_платежи!$B$2:$B$73,IF($B$4="Все","*",$B$4),data_платежи!$C$2:$C$73,IF($B$5="Все","*",$B$5),data_платежи!$D$2:$D$73,IF($B$6="Все","*",$B$6)) -> 1.2412567e+08 | B9: =SUMIFS(data_платежи!$E$2:$E$73,data_платежи!$B$2:$B$73,IF($B$4="Все","*",$B$4),data_платежи!$C$2:$C$73,IF($B$5="Все","*",$B$5),data_платежи!$D$2:$D$73,IF($B$6="Все","*",$B$6)) -> 25223 | C9: =IFERROR(SUMIFS(data_платежи!$F$2:$F$73,data_платежи!$B$2:$B$73,IF($B$4="Все","*",$B$4),data_платежи!$C$2:$C$73,IF($B$5="Все","*",$B$5),data_платежи!$D$2:$D$73,IF($B$6="Все","*",$B$6))/B9,0) -> 0.88010942 | D9: =SUMIFS(data_платежи!$I$2:$I$73,data_платежи!$B$2:$B$73,IF($B$4="Все","*",$B$4),data_платежи!$C$2:$C$73,IF($B$5="Все","*",$B$5),data_платежи!$D$2:$D$73,IF($B$6="Все","*",$B$6)) -> 2753884.1 | E9: =IFERROR(D9/A9,0) -> 0.022186258
A12: По провайдерам
A13: PSP | B13: Доля успешных | C13: Оборот, ₽ | D13: Комиссии, ₽ | E13: Эффективная комиссия | F13: Отклонено, шт.
A14: PSP Alfa | B14: =IFERROR(SUMIFS(data_платежи!$F$2:$F$73,data_платежи!$B$2:$B$73,$A14,data_платежи!$C$2:$C$73,IF($B$5="Все","*",$B$5),data_платежи!$D$2:$D$73,IF($B$6="Все","*",$B$6))/SUMIFS(data_платежи!$E$2:$E$73,data_платежи!$B$2:$B$73,$A14,data_платежи!$C$2:$C$73,IF($B$5="Все","*",$B$5),data_платежи!$D$2:$D$73,IF($B$6="Все","*",$B$6)),0) -> 0.91945117 | C14: =SUMIFS(data_платежи!$H$2:$H$73,data_платежи!$B$2:$B$73,$A14,data_платежи!$C$2:$C$73,IF($B$5="Все","*",$B$5),data_платежи!$D$2:$D$73,IF($B$6="Все","*",$B$6)) -> 63081038 | D14: =SUMIFS(data_платежи!$I$2:$I$73,data_платежи!$B$2:$B$73,$A14,data_платежи!$C$2:$C$73,IF($B$5="Все","*",$B$5),data_платежи!$D$2:$D$73,IF($B$6="Все","*",$B$6)) -> 1178920.5 | E14: =IFERROR(D14/C14,0) -> 0.018688983 | F14: =SUMIFS(data_платежи!$G$2:$G$73,data_платежи!$B$2:$B$73,$A14,data_платежи!$C$2:$C$73,IF($B$5="Все","*",$B$5),data_платежи!$D$2:$D$73,IF($B$6="Все","*",$B$6)) -> 998
